Traceback (most recent call last):
  File "C:\Python313\Lib\threading.py", line 1043, in _bootstrap_inner
    self.run()
    ~~~~~~~~^^
  File "C:\Python313\Lib\threading.py", line 994, in run
    self._target(*self._args, **self._kwargs)
    ~~~~~~~~~~~~^^^^^^^^^^^^^^^^^^^^^^^^^^^^^
  File "C:\Users\User\AppData\Roaming\Python\Python313\site-packages\django\utils\autoreload.py", line 64, in wrapper
    fn(*args, **kwargs)
    ~~^^^^^^^^^^^^^^^^^
  File "C:\Users\User\AppData\Roaming\Python\Python313\site-packages\django\core\management\commands\runserver.py", line 134, in inner_run
    self.check(**check_kwargs)
    ~~~~~~~~~~^^^^^^^^^^^^^^^^
  File "C:\Users\User\AppData\Roaming\Python\Python313\site-packages\django\core\management\base.py", line 492, in check
    all_issues = checks.run_checks(
        app_configs=app_configs,
    ...<2 lines>...
        databases=databases,
    )
  File "C:\Users\User\AppData\Roaming\Python\Python313\site-packages\django\core\checks\registry.py", line 89, in run_checks
    new_errors = check(app_configs=app_configs, databases=databases)
  File "C:\Users\User\AppData\Roaming\Python\Python313\site-packages\django\core\checks\urls.py", line 16, in check_url_config
    return check_resolver(resolver)
  File "C:\Users\User\AppData\Roaming\Python\Python313\site-packages\django\core\checks\urls.py", line 26, in check_resolver
    return check_method()
  File "C:\Users\User\AppData\Roaming\Python\Python313\site-packages\django\urls\resolvers.py", line 531, in check
    for pattern in self.url_patterns:
                   ^^^^^^^^^^^^^^^^^
  File "C:\Users\User\AppData\Roaming\Python\Python313\site-packages\django\utils\functional.py", line 47, in __get__
    res = instance.__dict__[self.name] = self.func(instance)
                                         ~~~~~~~~~^^^^^^^^^^
  File "C:\Users\User\AppData\Roaming\Python\Python313\site-packages\django\urls\resolvers.py", line 718, in url_patterns
    patterns = getattr(self.urlconf_module, "urlpatterns", self.urlconf_module)
                       ^^^^^^^^^^^^^^^^^^^
  File "C:\Users\User\AppData\Roaming\Python\Python313\site-packages\django\utils\functional.py", line 47, in __get__
    res = instance.__dict__[self.name] = self.func(instance)
                                         ~~~~~~~~~^^^^^^^^^^
  File "C:\Users\User\AppData\Roaming\Python\Python313\site-packages\django\urls\resolvers.py", line 711, in urlconf_module
    return import_module(self.urlconf_name)
  File "C:\Python313\Lib\importlib\__init__.py", line 88, in import_module
    return _bootstrap._gcd_import(name[level:], package, level)
           ~~~~~~~~~~~~~~~~~~~~~~^^^^^^^^^^^^^^^^^^^^^^^^^^^^^^
  File "<frozen importlib._bootstrap>", line 1387, in _gcd_import
  File "<frozen importlib._bootstrap>", line 1360, in _find_and_load
  File "<frozen importlib._bootstrap>", line 1331, in _find_and_load_unlocked
  File "<frozen importlib._bootstrap>", line 935, in _load_unlocked
  File "<frozen importlib._bootstrap_external>", line 1026, in exec_module
  File "<frozen importlib._bootstrap>", line 488, in _call_with_frames_removed
  File "C:\Users\User\Documents\djangoReconhecimento\sistemaAmbiental\urls.py", line 22, in <module>
    path('', include('core.urls', namespace='core')),
             ~~~~~~~^^^^^^^^^^^^^^^^^^^^^^^^^^^^^^^
  File "C:\Users\User\AppData\Roaming\Python\Python313\site-packages\django\urls\conf.py", line 39, in include
    urlconf_module = import_module(urlconf_module)
  File "C:\Python313\Lib\importlib\__init__.py", line 88, in import_module
    return _bootstrap._gcd_import(name[level:], package, level)
           ~~~~~~~~~~~~~~~~~~~~~~^^^^^^^^^^^^^^^^^^^^^^^^^^^^^^
  File "<frozen importlib._bootstrap>", line 1387, in _gcd_import
  File "<frozen importlib._bootstrap>", line 1360, in _find_and_load
  File "<frozen importlib._bootstrap>", line 1331, in _find_and_load_unlocked
  File "<frozen importlib._bootstrap>", line 935, in _load_unlocked
  File "<frozen importlib._bootstrap_external>", line 1026, in exec_module
  File "<frozen importlib._bootstrap>", line 488, in _call_with_frames_removed
  File "C:\Users\User\Documents\djangoReconhecimento\core\urls.py", line 2, in <module>
    from . import views
  File "C:\Users\User\Documents\djangoReconhecimento\core\views.py", line 8, in <module>
    from deepface import DeepFace
  File "C:\Users\User\AppData\Roaming\Python\Python313\site-packages\deepface\DeepFace.py", line 20, in <module>
    from deepface.modules import (
    ...<8 lines>...
    )
  File "C:\Users\User\AppData\Roaming\Python\Python313\site-packages\deepface\modules\modeling.py", line 5, in <module>
    from deepface.models.facial_recognition import (
    ...<10 lines>...
    )
  File "C:\Users\User\AppData\Roaming\Python\Python313\site-packages\deepface\models\facial_recognition\VGGFace.py", line 8, in <module>
    from deepface.commons import package_utils, weight_utils
  File "C:\Users\User\AppData\Roaming\Python\Python313\site-packages\deepface\commons\weight_utils.py", line 19, in <module>
    from tensorflow.keras.models import Sequential
  File "C:\Users\User\AppData\Roaming\Python\Python313\site-packages\tf_keras\api\_v2\keras\__init__.py", line 3, in <module>
    from tf_keras.api._v2.keras import __internal__
  File "C:\Users\User\AppData\Roaming\Python\Python313\site-packages\tf_keras\__init__.py", line 3, in <module>
    from tf_keras import __internal__
  File "C:\Users\User\AppData\Roaming\Python\Python313\site-packages\tf_keras\__internal__\__init__.py", line 6, in <module>
    from tf_keras.__internal__ import models
  File "C:\Users\User\AppData\Roaming\Python\Python313\site-packages\tf_keras\__internal__\models\__init__.py", line 3, in <module>
    from tf_keras.src.models.cloning import clone_and_build_model
  File "C:\Users\User\AppData\Roaming\Python\Python313\site-packages\tf_keras\src\__init__.py", line 21, in <module>
    from tf_keras.src import applications
  File "C:\Users\User\AppData\Roaming\Python\Python313\site-packages\tf_keras\src\applications\__init__.py", line 18, in <module>
    from tf_keras.src.applications.convnext import ConvNeXtBase
  File "C:\Users\User\AppData\Roaming\Python\Python313\site-packages\tf_keras\src\applications\convnext.py", line 33, in <module>
    from tf_keras.src.engine import sequential
  File "C:\Users\User\AppData\Roaming\Python\Python313\site-packages\tf_keras\src\engine\sequential.py", line 24, in <module>
    from tf_keras.src.engine import functional
  File "C:\Users\User\AppData\Roaming\Python\Python313\site-packages\tf_keras\src\engine\functional.py", line 33, in <module>
    from tf_keras.src.engine import training as training_lib
  File "C:\Users\User\AppData\Roaming\Python\Python313\site-packages\tf_keras\src\engine\training.py", line 48, in <module>
    from tf_keras.src.saving import saving_api
  File "C:\Users\User\AppData\Roaming\Python\Python313\site-packages\tf_keras\src\saving\saving_api.py", line 25, in <module>
    from tf_keras.src.saving.legacy import save as legacy_sm_saving_lib
  File "C:\Users\User\AppData\Roaming\Python\Python313\site-packages\tf_keras\src\saving\legacy\save.py", line 27, in <module>
    from tf_keras.src.saving.legacy.saved_model import load_context
  File "C:\Users\User\AppData\Roaming\Python\Python313\site-packages\tf_keras\src\saving\legacy\saved_model\load_context.py", line 68, in <module>
    tf.__internal__.register_load_context_function(in_load_context)